Traceback (most recent call last):
  File "C:\Users\kaes1\AppData\Local\Programs\Python\Python311\Lib\site-packages\jupyter_cache\executors\utils.py", line 58, in single_nb_execution
    executenb(
  File "C:\Users\kaes1\AppData\Local\Programs\Python\Python311\Lib\site-packages\nbclient\client.py", line 1305, in execute
    return NotebookClient(nb=nb, resources=resources, km=km, **kwargs).execute()
           ^^^^^^^^^^^^^^^^^^^^^^^^^^^^^^^^^^^^^^^^^^^^^^^^^^^^^^^^^^^^^^^^^^^^^
  File "C:\Users\kaes1\AppData\Local\Programs\Python\Python311\Lib\site-packages\jupyter_core\utils\__init__.py", line 168, in wrapped
    return loop.run_until_complete(inner)
           ^^^^^^^^^^^^^^^^^^^^^^^^^^^^^^
  File "C:\Users\kaes1\AppData\Local\Programs\Python\Python311\Lib\asyncio\base_events.py", line 653, in run_until_complete
    return future.result()
           ^^^^^^^^^^^^^^^
  File "C:\Users\kaes1\AppData\Local\Programs\Python\Python311\Lib\site-packages\nbclient\client.py", line 705, in async_execute
    await self.async_execute_cell(
  File "C:\Users\kaes1\AppData\Local\Programs\Python\Python311\Lib\site-packages\nbclient\client.py", line 1058, in async_execute_cell
    await self._check_raise_for_error(cell, cell_index, exec_reply)
  File "C:\Users\kaes1\AppData\Local\Programs\Python\Python311\Lib\site-packages\nbclient\client.py", line 914, in _check_raise_for_error
    raise CellExecutionError.from_cell_and_msg(cell, exec_reply_content)
nbclient.exceptions.CellExecutionError: An error occurred while executing the following cell:
------------------
import pandas as pd
import plotly.express as px
import plotly.graph_objects as go
from dash import Dash, dcc, html, Input, Output

app = Dash(__name__)

df = pd.read_csv("https://raw.githubusercontent.com/lihkir/Uninorte/main/AppliedStatisticMS/DataVisualizationRPython/Lectures/Python/PythonDataSets/intro_bees.csv")

df = df.groupby(['State', 'ANSI', 'Affected by', 'Year', 'state_code'])[['Pct of Colonies Impacted']].mean()
df.reset_index(inplace=True)
print(df[:5])

app.layout = html.Div([
    html.H1("Porcentaje promedio de colonias de abejas afectadas por enfermedad", style={'text-align': 'center'}),
    html.Div(
    dcc.Slider(id="slct_year",
                 value=2015,
                 marks={2015: '2015',
                        2016: '2016',
                        2017: '2017',
                        2018: '2018'}
                 ), hidden=True),
    html.Div(id='output_container', children=[]),
    html.Br(),
    dcc.Graph(id='my_bee_map', figure={})
])

@app.callback(
    # [Output(component_id='output_container', component_property='children'),
    Output(component_id='my_bee_map', component_property='figure',),
    [Input(component_id='slct_year', component_property='value')]
)
def display_animated_graph(soption_slctd):
    
    dff = df.copy()
    # dff = dff[dff["Year"] == option_slctd]
    dff = dff[dff["Affected by"] == "Varroa_mites"]
    
    animation = px.choropleth(
            data_frame=dff,
            locationmode='USA-states',
            locations='state_code',
            scope="usa",
            color='Pct of Colonies Impacted',
            hover_data=['State', 'Pct of Colonies Impacted'],
            color_continuous_scale=px.colors.sequential.deep,
            labels={'Pct of Colonies Impacted': '% of Bee Colonies'},
            template='plotly_white',
            animation_frame='Year',
            animation_group="State"
            
        )
    
    
    return animation

if __name__ == '__main__':
    # app.run_server(debug=True)
    app.run_server(debug=True, host='0.0.0.0', port=9000)
------------------

----- stdout -----
     State  ANSI Affected by  Year state_code  Pct of Colonies Impacted
0  Alabama     1     Disease  2015         AL                      0.05
1  Alabama     1     Disease  2016         AL                      1.20
2  Alabama     1     Disease  2017         AL                      2.25
3  Alabama     1     Disease  2018         AL                      1.30
4  Alabama     1     Disease  2019         AL                      1.80
------------------

[1;31m---------------------------------------------------------------------------[0m
[1;31mOSError[0m                                   Traceback (most recent call last)
File [1;32m~\AppData\Local\Programs\Python\Python311\Lib\site-packages\urllib3\connection.py:174[0m, in [0;36mHTTPConnection._new_conn[1;34m(self)[0m
[0;32m    173[0m [38;5;28;01mtry[39;00m:
[1;32m--> 174[0m     conn [38;5;241m=[39m [43mconnection[49m[38;5;241;43m.[39;49m[43mcreate_connection[49m[43m([49m
[0;32m    175[0m [43m        [49m[43m([49m[38;5;28;43mself[39;49m[38;5;241;43m.[39;49m[43m_dns_host[49m[43m,[49m[43m [49m[38;5;28;43mself[39;49m[38;5;241;43m.[39;49m[43mport[49m[43m)[49m[43m,[49m[43m [49m[38;5;28;43mself[39;49m[38;5;241;43m.[39;49m[43mtimeout[49m[43m,[49m[43m [49m[38;5;241;43m*[39;49m[38;5;241;43m*[39;49m[43mextra_kw[49m
[0;32m    176[0m [43m    [49m[43m)[49m
[0;32m    178[0m [38;5;28;01mexcept[39;00m SocketTimeout:

File [1;32m~\AppData\Local\Programs\Python\Python311\Lib\site-packages\urllib3\util\connection.py:95[0m, in [0;36mcreate_connection[1;34m(address, timeout, source_address, socket_options)[0m
[0;32m     94[0m [38;5;28;01mif[39;00m err [38;5;129;01mis[39;00m [38;5;129;01mnot[39;00m [38;5;28;01mNone[39;00m:
[1;32m---> 95[0m     [38;5;28;01mraise[39;00m err
[0;32m     97[0m [38;5;28;01mraise[39;00m socket[38;5;241m.[39merror([38;5;124m"[39m[38;5;124mgetaddrinfo returns an empty list[39m[38;5;124m"[39m)

File [1;32m~\AppData\Local\Programs\Python\Python311\Lib\site-packages\urllib3\util\connection.py:85[0m, in [0;36mcreate_connection[1;34m(address, timeout, source_address, socket_options)[0m
[0;32m     84[0m     sock[38;5;241m.[39mbind(source_address)
[1;32m---> 85[0m sock[38;5;241m.[39mconnect(sa)
[0;32m     86[0m [38;5;28;01mreturn[39;00m sock

[1;31mOSError[0m: [WinError 10049] The requested address is not valid in its context

During handling of the above exception, another exception occurred:

[1;31mNewConnectionError[0m                        Traceback (most recent call last)
File [1;32m~\AppData\Local\Programs\Python\Python311\Lib\site-packages\urllib3\connectionpool.py:714[0m, in [0;36mHTTPConnectionPool.urlopen[1;34m(self, method, url, body, headers, retries, redirect, assert_same_host, timeout, pool_timeout, release_conn, chunked, body_pos, **response_kw)[0m
[0;32m    713[0m [38;5;66;03m# Make the request on the httplib connection object.[39;00m
[1;32m--> 714[0m httplib_response [38;5;241m=[39m [38;5;28;43mself[39;49m[38;5;241;43m.[39;49m[43m_make_request[49m[43m([49m
[0;32m    715[0m [43m    [49m[43mconn[49m[43m,[49m
[0;32m    716[0m [43m    [49m[43mmethod[49m[43m,[49m
[0;32m    717[0m [43m    [49m[43murl[49m[43m,[49m
[0;32m    718[0m [43m    [49m[43mtimeout[49m[38;5;241;43m=[39;49m[43mtimeout_obj[49m[43m,[49m
[0;32m    719[0m [43m    [49m[43mbody[49m[38;5;241;43m=[39;49m[43mbody[49m[43m,[49m
[0;32m    720[0m [43m    [49m[43mheaders[49m[38;5;241;43m=[39;49m[43mheaders[49m[43m,[49m
[0;32m    721[0m [43m    [49m[43mchunked[49m[38;5;241;43m=[39;49m[43mchunked[49m[43m,[49m
[0;32m    722[0m [43m[49m[43m)[49m
[0;32m    724[0m [38;5;66;03m# If we're going to release the connection in ``finally:``, then[39;00m
[0;32m    725[0m [38;5;66;03m# the response doesn't need to know about the connection. Otherwise[39;00m
[0;32m    726[0m [38;5;66;03m# it will also try to release it and we'll have a double-release[39;00m
[0;32m    727[0m [38;5;66;03m# mess.[39;00m

File [1;32m~\AppData\Local\Programs\Python\Python311\Lib\site-packages\urllib3\connectionpool.py:415[0m, in [0;36mHTTPConnectionPool._make_request[1;34m(self, conn, method, url, timeout, chunked, **httplib_request_kw)[0m
[0;32m    414[0m     [38;5;28;01melse[39;00m:
[1;32m--> 415[0m         [43mconn[49m[38;5;241;43m.[39;49m[43mrequest[49m[43m([49m[43mmethod[49m[43m,[49m[43m [49m[43murl[49m[43m,[49m[43m [49m[38;5;241;43m*[39;49m[38;5;241;43m*[39;49m[43mhttplib_request_kw[49m[43m)[49m
[0;32m    417[0m [38;5;66;03m# We are swallowing BrokenPipeError (errno.EPIPE) since the server is[39;00m
[0;32m    418[0m [38;5;66;03m# legitimately able to close the connection after sending a valid response.[39;00m
[0;32m    419[0m [38;5;66;03m# With this behaviour, the received response is still readable.[39;00m

File [1;32m~\AppData\Local\Programs\Python\Python311\Lib\site-packages\urllib3\connection.py:244[0m, in [0;36mHTTPConnection.request[1;34m(self, method, url, body, headers)[0m
[0;32m    243[0m     headers[[38;5;124m"[39m[38;5;124mUser-Agent[39m[38;5;124m"[39m] [38;5;241m=[39m _get_default_user_agent()
[1;32m--> 244[0m [38;5;28;43msuper[39;49m[43m([49m[43mHTTPConnection[49m[43m,[49m[43m [49m[38;5;28;43mself[39;49m[43m)[49m[38;5;241;43m.[39;49m[43mrequest[49m[43m([49m[43mmethod[49m[43m,[49m[43m [49m[43murl[49m[43m,[49m[43m [49m[43mbody[49m[38;5;241;43m=[39;49m[43mbody[49m[43m,[49m[43m [49m[43mheaders[49m[38;5;241;43m=[39;49m[43mheaders[49m[43m)[49m

File [1;32m~\AppData\Local\Programs\Python\Python311\Lib\http\client.py:1286[0m, in [0;36mHTTPConnection.request[1;34m(self, method, url, body, headers, encode_chunked)[0m
[0;32m   1285[0m [38;5;250m[39m[38;5;124;03m"""Send a complete request to the server."""[39;00m
[1;32m-> 1286[0m [38;5;28;43mself[39;49m[38;5;241;43m.[39;49m[43m_send_request[49m[43m([49m[43mmethod[49m[43m,[49m[43m [49m[43murl[49m[43m,[49m[43m [49m[43mbody[49m[43m,[49m[43m [49m[43mheaders[49m[43m,[49m[43m [49m[43mencode_chunked[49m[43m)[49m

File [1;32m~\AppData\Local\Programs\Python\Python311\Lib\http\client.py:1332[0m, in [0;36mHTTPConnection._send_request[1;34m(self, method, url, body, headers, encode_chunked)[0m
[0;32m   1331[0m     body [38;5;241m=[39m _encode(body, [38;5;124m'[39m[38;5;124mbody[39m[38;5;124m'[39m)
[1;32m-> 1332[0m [38;5;28;43mself[39;49m[38;5;241;43m.[39;49m[43mendheaders[49m[43m([49m[43mbody[49m[43m,[49m[43m [49m[43mencode_chunked[49m[38;5;241;43m=[39;49m[43mencode_chunked[49m[43m)[49m

File [1;32m~\AppData\Local\Programs\Python\Python311\Lib\http\client.py:1281[0m, in [0;36mHTTPConnection.endheaders[1;34m(self, message_body, encode_chunked)[0m
[0;32m   1280[0m     [38;5;28;01mraise[39;00m CannotSendHeader()
[1;32m-> 1281[0m [38;5;28;43mself[39;49m[38;5;241;43m.[39;49m[43m_send_output[49m[43m([49m[43mmessage_body[49m[43m,[49m[43m [49m[43mencode_chunked[49m[38;5;241;43m=[39;49m[43mencode_chunked[49m[43m)[49m

File [1;32m~\AppData\Local\Programs\Python\Python311\Lib\http\client.py:1041[0m, in [0;36mHTTPConnection._send_output[1;34m(self, message_body, encode_chunked)[0m
[0;32m   1040[0m [38;5;28;01mdel[39;00m [38;5;28mself[39m[38;5;241m.[39m_buffer[:]
[1;32m-> 1041[0m [38;5;28;43mself[39;49m[38;5;241;43m.[39;49m[43msend[49m[43m([49m[43mmsg[49m[43m)[49m
[0;32m   1043[0m [38;5;28;01mif[39;00m message_body [38;5;129;01mis[39;00m [38;5;129;01mnot[39;00m [38;5;28;01mNone[39;00m:
[0;32m   1044[0m 
[0;32m   1045[0m     [38;5;66;03m# create a consistent interface to message_body[39;00m

File [1;32m~\AppData\Local\Programs\Python\Python311\Lib\http\client.py:979[0m, in [0;36mHTTPConnection.send[1;34m(self, data)[0m
[0;32m    978[0m [38;5;28;01mif[39;00m [38;5;28mself[39m[38;5;241m.[39mauto_open:
[1;32m--> 979[0m     [38;5;28;43mself[39;49m[38;5;241;43m.[39;49m[43mconnect[49m[43m([49m[43m)[49m
[0;32m    980[0m [38;5;28;01melse[39;00m:

File [1;32m~\AppData\Local\Programs\Python\Python311\Lib\site-packages\urllib3\connection.py:205[0m, in [0;36mHTTPConnection.connect[1;34m(self)[0m
[0;32m    204[0m [38;5;28;01mdef[39;00m [38;5;21mconnect[39m([38;5;28mself[39m):
[1;32m--> 205[0m     conn [38;5;241m=[39m [38;5;28;43mself[39;49m[38;5;241;43m.[39;49m[43m_new_conn[49m[43m([49m[43m)[49m
[0;32m    206[0m     [38;5;28mself[39m[38;5;241m.[39m_prepare_conn(conn)

File [1;32m~\AppData\Local\Programs\Python\Python311\Lib\site-packages\urllib3\connection.py:186[0m, in [0;36mHTTPConnection._new_conn[1;34m(self)[0m
[0;32m    185[0m [38;5;28;01mexcept[39;00m SocketError [38;5;28;01mas[39;00m e:
[1;32m--> 186[0m     [38;5;28;01mraise[39;00m NewConnectionError(
[0;32m    187[0m         [38;5;28mself[39m, [38;5;124m"[39m[38;5;124mFailed to establish a new connection: [39m[38;5;132;01m%s[39;00m[38;5;124m"[39m [38;5;241m%[39m e
[0;32m    188[0m     )
[0;32m    190[0m [38;5;28;01mreturn[39;00m conn

[1;31mNewConnectionError[0m: <urllib3.connection.HTTPConnection object at 0x000001E5BFF88B10>: Failed to establish a new connection: [WinError 10049] The requested address is not valid in its context

During handling of the above exception, another exception occurred:

[1;31mMaxRetryError[0m                             Traceback (most recent call last)
File [1;32m~\AppData\Local\Programs\Python\Python311\Lib\site-packages\requests\adapters.py:486[0m, in [0;36mHTTPAdapter.send[1;34m(self, request, stream, timeout, verify, cert, proxies)[0m
[0;32m    485[0m [38;5;28;01mtry[39;00m:
[1;32m--> 486[0m     resp [38;5;241m=[39m [43mconn[49m[38;5;241;43m.[39;49m[43murlopen[49m[43m([49m
[0;32m    487[0m [43m        [49m[43mmethod[49m[38;5;241;43m=[39;49m[43mrequest[49m[38;5;241;43m.[39;49m[43mmethod[49m[43m,[49m
[0;32m    488[0m [43m        [49m[43murl[49m[38;5;241;43m=[39;49m[43murl[49m[43m,[49m
[0;32m    489[0m [43m        [49m[43mbody[49m[38;5;241;43m=[39;49m[43mrequest[49m[38;5;241;43m.[39;49m[43mbody[49m[43m,[49m
[0;32m    490[0m [43m        [49m[43mheaders[49m[38;5;241;43m=[39;49m[43mrequest[49m[38;5;241;43m.[39;49m[43mheaders[49m[43m,[49m
[0;32m    491[0m [43m        [49m[43mredirect[49m[38;5;241;43m=[39;49m[38;5;28;43;01mFalse[39;49;00m[43m,[49m
[0;32m    492[0m [43m        [49m[43massert_same_host[49m[38;5;241;43m=[39;49m[38;5;28;43;01mFalse[39;49;00m[43m,[49m
[0;32m    493[0m [43m        [49m[43mpreload_content[49m[38;5;241;43m=[39;49m[38;5;28;43;01mFalse[39;49;00m[43m,[49m
[0;32m    494[0m [43m        [49m[43mdecode_content[49m[38;5;241;43m=[39;49m[38;5;28;43;01mFalse[39;49;00m[43m,[49m
[0;32m    495[0m [43m        [49m[43mretries[49m[38;5;241;43m=[39;49m[38;5;28;43mself[39;49m[38;5;241;43m.[39;49m[43mmax_retries[49m[43m,[49m
[0;32m    496[0m [43m        [49m[43mtimeout[49m[38;5;241;43m=[39;49m[43mtimeout[49m[43m,[49m
[0;32m    497[0m [43m        [49m[43mchunked[49m[38;5;241;43m=[39;49m[43mchunked[49m[43m,[49m
[0;32m    498[0m [43m    [49m[43m)[49m
[0;32m    500[0m [38;5;28;01mexcept[39;00m (ProtocolError, [38;5;167;01mOSError[39;00m) [38;5;28;01mas[39;00m err:

File [1;32m~\AppData\Local\Programs\Python\Python311\Lib\site-packages\urllib3\connectionpool.py:798[0m, in [0;36mHTTPConnectionPool.urlopen[1;34m(self, method, url, body, headers, retries, redirect, assert_same_host, timeout, pool_timeout, release_conn, chunked, body_pos, **response_kw)[0m
[0;32m    796[0m     e [38;5;241m=[39m ProtocolError([38;5;124m"[39m[38;5;124mConnection aborted.[39m[38;5;124m"[39m, e)
[1;32m--> 798[0m retries [38;5;241m=[39m [43mretries[49m[38;5;241;43m.[39;49m[43mincrement[49m[43m([49m
[0;32m    799[0m [43m    [49m[43mmethod[49m[43m,[49m[43m [49m[43murl[49m[43m,[49m[43m [49m[43merror[49m[38;5;241;43m=[39;49m[43me[49m[43m,[49m[43m [49m[43m_pool[49m[38;5;241;43m=[39;49m[38;5;28;43mself[39;49m[43m,[49m[43m [49m[43m_stacktrace[49m[38;5;241;43m=[39;49m[43msys[49m[38;5;241;43m.[39;49m[43mexc_info[49m[43m([49m[43m)[49m[43m[[49m[38;5;241;43m2[39;49m[43m][49m
[0;32m    800[0m [43m[49m[43m)[49m
[0;32m    801[0m retries[38;5;241m.[39msleep()

File [1;32m~\AppData\Local\Programs\Python\Python311\Lib\site-packages\urllib3\util\retry.py:592[0m, in [0;36mRetry.increment[1;34m(self, method, url, response, error, _pool, _stacktrace)[0m
[0;32m    591[0m [38;5;28;01mif[39;00m new_retry[38;5;241m.[39mis_exhausted():
[1;32m--> 592[0m     [38;5;28;01mraise[39;00m MaxRetryError(_pool, url, error [38;5;129;01mor[39;00m ResponseError(cause))
[0;32m    594[0m log[38;5;241m.[39mdebug([38;5;124m"[39m[38;5;124mIncremented Retry for (url=[39m[38;5;124m'[39m[38;5;132;01m%s[39;00m[38;5;124m'[39m[38;5;124m): [39m[38;5;132;01m%r[39;00m[38;5;124m"[39m, url, new_retry)

[1;31mMaxRetryError[0m: HTTPConnectionPool(host='0.0.0.0', port=9000): Max retries exceeded with url: /_alive_0aef06bd-7f4f-4dcf-bfcf-8abacd33cd6c (Caused by NewConnectionError('<urllib3.connection.HTTPConnection object at 0x000001E5BFF88B10>: Failed to establish a new connection: [WinError 10049] The requested address is not valid in its context'))

During handling of the above exception, another exception occurred:

[1;31mConnectionError[0m                           Traceback (most recent call last)
Cell [1;32mIn[1], line 60[0m
[0;32m     56[0m     [38;5;28;01mreturn[39;00m animation
[0;32m     58[0m [38;5;28;01mif[39;00m [38;5;18m__name__[39m [38;5;241m==[39m [38;5;124m'[39m[38;5;124m__main__[39m[38;5;124m'[39m:
[0;32m     59[0m     [38;5;66;03m# app.run_server(debug=True)[39;00m
[1;32m---> 60[0m     [43mapp[49m[38;5;241;43m.[39;49m[43mrun_server[49m[43m([49m[43mdebug[49m[38;5;241;43m=[39;49m[38;5;28;43;01mTrue[39;49;00m[43m,[49m[43m [49m[43mhost[49m[38;5;241;43m=[39;49m[38;5;124;43m'[39;49m[38;5;124;43m0.0.0.0[39;49m[38;5;124;43m'[39;49m[43m,[49m[43m [49m[43mport[49m[38;5;241;43m=[39;49m[38;5;241;43m9000[39;49m[43m)[49m

File [1;32m~\AppData\Local\Programs\Python\Python311\Lib\site-packages\dash\dash.py:2175[0m, in [0;36mDash.run_server[1;34m(self, *args, **kwargs)[0m
[0;32m   2169[0m [38;5;28;01mdef[39;00m [38;5;21mrun_server[39m([38;5;28mself[39m, [38;5;241m*[39margs, [38;5;241m*[39m[38;5;241m*[39mkwargs):
[0;32m   2170[0m [38;5;250m    [39m[38;5;124;03m"""`run_server` is a deprecated alias of `run` and may be removed in a[39;00m
[0;32m   2171[0m [38;5;124;03m    future version. We recommend using `app.run` instead.[39;00m
[0;32m   2172[0m 
[0;32m   2173[0m [38;5;124;03m    See `app.run` for usage information.[39;00m
[0;32m   2174[0m [38;5;124;03m    """[39;00m
[1;32m-> 2175[0m     [38;5;28;43mself[39;49m[38;5;241;43m.[39;49m[43mrun[49m[43m([49m[38;5;241;43m*[39;49m[43margs[49m[43m,[49m[43m [49m[38;5;241;43m*[39;49m[38;5;241;43m*[39;49m[43mkwargs[49m[43m)[49m

File [1;32m~\AppData\Local\Programs\Python\Python311\Lib\site-packages\dash\dash.py:2066[0m, in [0;36mDash.run[1;34m(self, host, port, proxy, debug, jupyter_mode, jupyter_width, jupyter_height, jupyter_server_url, dev_tools_ui, dev_tools_props_check, dev_tools_serve_dev_bundles, dev_tools_hot_reload, dev_tools_hot_reload_interval, dev_tools_hot_reload_watch_interval, dev_tools_hot_reload_max_retry, dev_tools_silence_routes_logging, dev_tools_prune_errors, **flask_run_options)[0m
[0;32m   2063[0m             extra_files[38;5;241m.[39mappend(path)
[0;32m   2065[0m [38;5;28;01mif[39;00m jupyter_dash[38;5;241m.[39mactive:
[1;32m-> 2066[0m     [43mjupyter_dash[49m[38;5;241;43m.[39;49m[43mrun_app[49m[43m([49m
[0;32m   2067[0m [43m        [49m[38;5;28;43mself[39;49m[43m,[49m
[0;32m   2068[0m [43m        [49m[43mmode[49m[38;5;241;43m=[39;49m[43mjupyter_mode[49m[43m,[49m
[0;32m   2069[0m [43m        [49m[43mwidth[49m[38;5;241;43m=[39;49m[43mjupyter_width[49m[43m,[49m
[0;32m   2070[0m [43m        [49m[43mheight[49m[38;5;241;43m=[39;49m[43mjupyter_height[49m[43m,[49m
[0;32m   2071[0m [43m        [49m[43mhost[49m[38;5;241;43m=[39;49m[43mhost[49m[43m,[49m
[0;32m   2072[0m [43m        [49m[43mport[49m[38;5;241;43m=[39;49m[43mport[49m[43m,[49m
[0;32m   2073[0m [43m        [49m[43mserver_url[49m[38;5;241;43m=[39;49m[43mjupyter_server_url[49m[43m,[49m
[0;32m   2074[0m [43m    [49m[43m)[49m
[0;32m   2075[0m [38;5;28;01melse[39;00m:
[0;32m   2076[0m     [38;5;28mself[39m[38;5;241m.[39mserver[38;5;241m.[39mrun(host[38;5;241m=[39mhost, port[38;5;241m=[39mport, debug[38;5;241m=[39mdebug, [38;5;241m*[39m[38;5;241m*[39mflask_run_options)

File [1;32m~\AppData\Local\Programs\Python\Python311\Lib\site-packages\dash\_jupyter.py:401[0m, in [0;36mJupyterDash.run_app[1;34m(self, app, mode, width, height, host, port, server_url)[0m
[0;32m    399[0m     display(HTML(msg))
[0;32m    400[0m [38;5;28;01melse[39;00m:
[1;32m--> 401[0m     [38;5;28;01mraise[39;00m final_error

File [1;32m~\AppData\Local\Programs\Python\Python311\Lib\site-packages\dash\_jupyter.py:388[0m, in [0;36mJupyterDash.run_app[1;34m(self, app, mode, width, height, host, port, server_url)[0m
[0;32m    385[0m         [38;5;28;01mraise[39;00m err
[0;32m    387[0m [38;5;28;01mtry[39;00m:
[1;32m--> 388[0m     [43mwait_for_app[49m[43m([49m[43m)[49m
[0;32m    390[0m     [38;5;28;01mif[39;00m [38;5;28mself[39m[38;5;241m.[39min_colab:
[0;32m    391[0m         JupyterDash[38;5;241m.[39m_display_in_colab(dashboard_url, port, mode, width, height)

File [1;32m~\AppData\Local\Programs\Python\Python311\Lib\site-packages\retrying.py:56[0m, in [0;36mretry.<locals>.wrap.<locals>.wrapped_f[1;34m(*args, **kw)[0m
[0;32m     54[0m [38;5;129m@six[39m[38;5;241m.[39mwraps(f)
[0;32m     55[0m [38;5;28;01mdef[39;00m [38;5;21mwrapped_f[39m([38;5;241m*[39margs, [38;5;241m*[39m[38;5;241m*[39mkw):
[1;32m---> 56[0m     [38;5;28;01mreturn[39;00m [43mRetrying[49m[43m([49m[38;5;241;43m*[39;49m[43mdargs[49m[43m,[49m[43m [49m[38;5;241;43m*[39;49m[38;5;241;43m*[39;49m[43mdkw[49m[43m)[49m[38;5;241;43m.[39;49m[43mcall[49m[43m([49m[43mf[49m[43m,[49m[43m [49m[38;5;241;43m*[39;49m[43margs[49m[43m,[49m[43m [49m[38;5;241;43m*[39;49m[38;5;241;43m*[39;49m[43mkw[49m[43m)[49m

File [1;32m~\AppData\Local\Programs\Python\Python311\Lib\site-packages\retrying.py:266[0m, in [0;36mRetrying.call[1;34m(self, fn, *args, **kwargs)[0m
[0;32m    263[0m [38;5;28;01mif[39;00m [38;5;28mself[39m[38;5;241m.[39mstop(attempt_number, delay_since_first_attempt_ms):
[0;32m    264[0m     [38;5;28;01mif[39;00m [38;5;129;01mnot[39;00m [38;5;28mself[39m[38;5;241m.[39m_wrap_exception [38;5;129;01mand[39;00m attempt[38;5;241m.[39mhas_exception:
[0;32m    265[0m         [38;5;66;03m# get() on an attempt with an exception should cause it to be raised, but raise just in case[39;00m
[1;32m--> 266[0m         [38;5;28;01mraise[39;00m [43mattempt[49m[38;5;241;43m.[39;49m[43mget[49m[43m([49m[43m)[49m
[0;32m    267[0m     [38;5;28;01melse[39;00m:
[0;32m    268[0m         [38;5;28;01mraise[39;00m RetryError(attempt)

File [1;32m~\AppData\Local\Programs\Python\Python311\Lib\site-packages\retrying.py:301[0m, in [0;36mAttempt.get[1;34m(self, wrap_exception)[0m
[0;32m    299[0m         [38;5;28;01mraise[39;00m RetryError([38;5;28mself[39m)
[0;32m    300[0m     [38;5;28;01melse[39;00m:
[1;32m--> 301[0m         [43msix[49m[38;5;241;43m.[39;49m[43mreraise[49m[43m([49m[38;5;28;43mself[39;49m[38;5;241;43m.[39;49m[43mvalue[49m[43m[[49m[38;5;241;43m0[39;49m[43m][49m[43m,[49m[43m [49m[38;5;28;43mself[39;49m[38;5;241;43m.[39;49m[43mvalue[49m[43m[[49m[38;5;241;43m1[39;49m[43m][49m[43m,[49m[43m [49m[38;5;28;43mself[39;49m[38;5;241;43m.[39;49m[43mvalue[49m[43m[[49m[38;5;241;43m2[39;49m[43m][49m[43m)[49m
[0;32m    302[0m [38;5;28;01melse[39;00m:
[0;32m    303[0m     [38;5;28;01mreturn[39;00m [38;5;28mself[39m[38;5;241m.[39mvalue

File [1;32m~\AppData\Local\Programs\Python\Python311\Lib\site-packages\six.py:719[0m, in [0;36mreraise[1;34m(tp, value, tb)[0m
[0;32m    717[0m     [38;5;28;01mif[39;00m value[38;5;241m.[39m__traceback__ [38;5;129;01mis[39;00m [38;5;129;01mnot[39;00m tb:
[0;32m    718[0m         [38;5;28;01mraise[39;00m value[38;5;241m.[39mwith_traceback(tb)
[1;32m--> 719[0m     [38;5;28;01mraise[39;00m value
[0;32m    720[0m [38;5;28;01mfinally[39;00m:
[0;32m    721[0m     value [38;5;241m=[39m [38;5;28;01mNone[39;00m

File [1;32m~\AppData\Local\Programs\Python\Python311\Lib\site-packages\retrying.py:251[0m, in [0;36mRetrying.call[1;34m(self, fn, *args, **kwargs)[0m
[0;32m    248[0m     [38;5;28mself[39m[38;5;241m.[39m_before_attempts(attempt_number)
[0;32m    250[0m [38;5;28;01mtry[39;00m:
[1;32m--> 251[0m     attempt [38;5;241m=[39m Attempt([43mfn[49m[43m([49m[38;5;241;43m*[39;49m[43margs[49m[43m,[49m[43m [49m[38;5;241;43m*[39;49m[38;5;241;43m*[39;49m[43mkwargs[49m[43m)[49m, attempt_number, [38;5;28;01mFalse[39;00m)
[0;32m    252[0m [38;5;28;01mexcept[39;00m:
[0;32m    253[0m     tb [38;5;241m=[39m sys[38;5;241m.[39mexc_info()

File [1;32m~\AppData\Local\Programs\Python\Python311\Lib\site-packages\dash\_jupyter.py:385[0m, in [0;36mJupyterDash.run_app.<locals>.wait_for_app[1;34m()[0m
[0;32m    383[0m [38;5;28;01mexcept[39;00m requests[38;5;241m.[39mConnectionError [38;5;28;01mas[39;00m err:
[0;32m    384[0m     _get_error()
[1;32m--> 385[0m     [38;5;28;01mraise[39;00m err

File [1;32m~\AppData\Local\Programs\Python\Python311\Lib\site-packages\dash\_jupyter.py:372[0m, in [0;36mJupyterDash.run_app.<locals>.wait_for_app[1;34m()[0m
[0;32m    370[0m _get_error()
[0;32m    371[0m [38;5;28;01mtry[39;00m:
[1;32m--> 372[0m     req [38;5;241m=[39m [43mrequests[49m[38;5;241;43m.[39;49m[43mget[49m[43m([49m[43malive_url[49m[43m)[49m
[0;32m    373[0m     res [38;5;241m=[39m req[38;5;241m.[39mcontent[38;5;241m.[39mdecode()
[0;32m    374[0m     [38;5;28;01mif[39;00m req[38;5;241m.[39mstatus_code [38;5;241m!=[39m [38;5;241m200[39m:

File [1;32m~\AppData\Local\Programs\Python\Python311\Lib\site-packages\requests\api.py:73[0m, in [0;36mget[1;34m(url, params, **kwargs)[0m
[0;32m     62[0m [38;5;28;01mdef[39;00m [38;5;21mget[39m(url, params[38;5;241m=[39m[38;5;28;01mNone[39;00m, [38;5;241m*[39m[38;5;241m*[39mkwargs):
[0;32m     63[0m [38;5;250m    [39m[38;5;124mr[39m[38;5;124;03m"""Sends a GET request.[39;00m
[0;32m     64[0m 
[0;32m     65[0m [38;5;124;03m    :param url: URL for the new :class:`Request` object.[39;00m
[1;32m   (...)[0m
[0;32m     70[0m [38;5;124;03m    :rtype: requests.Response[39;00m
[0;32m     71[0m [38;5;124;03m    """[39;00m
[1;32m---> 73[0m     [38;5;28;01mreturn[39;00m [43mrequest[49m[43m([49m[38;5;124;43m"[39;49m[38;5;124;43mget[39;49m[38;5;124;43m"[39;49m[43m,[49m[43m [49m[43murl[49m[43m,[49m[43m [49m[43mparams[49m[38;5;241;43m=[39;49m[43mparams[49m[43m,[49m[43m [49m[38;5;241;43m*[39;49m[38;5;241;43m*[39;49m[43mkwargs[49m[43m)[49m

File [1;32m~\AppData\Local\Programs\Python\Python311\Lib\site-packages\requests\api.py:59[0m, in [0;36mrequest[1;34m(method, url, **kwargs)[0m
[0;32m     55[0m [38;5;66;03m# By using the 'with' statement we are sure the session is closed, thus we[39;00m
[0;32m     56[0m [38;5;66;03m# avoid leaving sockets open which can trigger a ResourceWarning in some[39;00m
[0;32m     57[0m [38;5;66;03m# cases, and look like a memory leak in others.[39;00m
[0;32m     58[0m [38;5;28;01mwith[39;00m sessions[38;5;241m.[39mSession() [38;5;28;01mas[39;00m session:
[1;32m---> 59[0m     [38;5;28;01mreturn[39;00m [43msession[49m[38;5;241;43m.[39;49m[43mrequest[49m[43m([49m[43mmethod[49m[38;5;241;43m=[39;49m[43mmethod[49m[43m,[49m[43m [49m[43murl[49m[38;5;241;43m=[39;49m[43murl[49m[43m,[49m[43m [49m[38;5;241;43m*[39;49m[38;5;241;43m*[39;49m[43mkwargs[49m[43m)[49m

File [1;32m~\AppData\Local\Programs\Python\Python311\Lib\site-packages\requests\sessions.py:589[0m, in [0;36mSession.request[1;34m(self, method, url, params, data, headers, cookies, files, auth, timeout, allow_redirects, proxies, hooks, stream, verify, cert, json)[0m
[0;32m    584[0m send_kwargs [38;5;241m=[39m {
[0;32m    585[0m     [38;5;124m"[39m[38;5;124mtimeout[39m[38;5;124m"[39m: timeout,
[0;32m    586[0m     [38;5;124m"[39m[38;5;124mallow_redirects[39m[38;5;124m"[39m: allow_redirects,
[0;32m    587[0m }
[0;32m    588[0m send_kwargs[38;5;241m.[39mupdate(settings)
[1;32m--> 589[0m resp [38;5;241m=[39m [38;5;28;43mself[39;49m[38;5;241;43m.[39;49m[43msend[49m[43m([49m[43mprep[49m[43m,[49m[43m [49m[38;5;241;43m*[39;49m[38;5;241;43m*[39;49m[43msend_kwargs[49m[43m)[49m
[0;32m    591[0m [38;5;28;01mreturn[39;00m resp

File [1;32m~\AppData\Local\Programs\Python\Python311\Lib\site-packages\requests\sessions.py:703[0m, in [0;36mSession.send[1;34m(self, request, **kwargs)[0m
[0;32m    700[0m start [38;5;241m=[39m preferred_clock()
[0;32m    702[0m [38;5;66;03m# Send the request[39;00m
[1;32m--> 703[0m r [38;5;241m=[39m [43madapter[49m[38;5;241;43m.[39;49m[43msend[49m[43m([49m[43mrequest[49m[43m,[49m[43m [49m[38;5;241;43m*[39;49m[38;5;241;43m*[39;49m[43mkwargs[49m[43m)[49m
[0;32m    705[0m [38;5;66;03m# Total elapsed time of the request (approximately)[39;00m
[0;32m    706[0m elapsed [38;5;241m=[39m preferred_clock() [38;5;241m-[39m start

File [1;32m~\AppData\Local\Programs\Python\Python311\Lib\site-packages\requests\adapters.py:519[0m, in [0;36mHTTPAdapter.send[1;34m(self, request, stream, timeout, verify, cert, proxies)[0m
[0;32m    515[0m     [38;5;28;01mif[39;00m [38;5;28misinstance[39m(e[38;5;241m.[39mreason, _SSLError):
[0;32m    516[0m         [38;5;66;03m# This branch is for urllib3 v1.22 and later.[39;00m
[0;32m    517[0m         [38;5;28;01mraise[39;00m SSLError(e, request[38;5;241m=[39mrequest)
[1;32m--> 519[0m     [38;5;28;01mraise[39;00m [38;5;167;01mConnectionError[39;00m(e, request[38;5;241m=[39mrequest)
[0;32m    521[0m [38;5;28;01mexcept[39;00m ClosedPoolError [38;5;28;01mas[39;00m e:
[0;32m    522[0m     [38;5;28;01mraise[39;00m [38;5;167;01mConnectionError[39;00m(e, request[38;5;241m=[39mrequest)

[1;31mConnectionError[0m: HTTPConnectionPool(host='0.0.0.0', port=9000): Max retries exceeded with url: /_alive_0aef06bd-7f4f-4dcf-bfcf-8abacd33cd6c (Caused by NewConnectionError('<urllib3.connection.HTTPConnection object at 0x000001E5BFF88B10>: Failed to establish a new connection: [WinError 10049] The requested address is not valid in its context'))

